<?xml version="1.0" encoding="utf-8"?>
<robot xmlns:xacro="http://www.ros.org/wiki/xacro"  name="leo_rover">

    <xacro:include filename="leo_gazebo.xacro"/>

    <!-- Base Footprint -->
    
    <link name="base_footprint"/>


    <!-- Base link -->

    <joint name="base_joint" type="fixed">
      <origin xyz="0 0 0.19783" rpy="0 0 0"/>
      <parent link="base_footprint"/>
      <child link="base_link"/>
    </joint>

    <link name="base_link">
      <inertial>
        <mass value="1.584994"/>
        <origin xyz="-0.019662 0.011643 -0.031802"/>
        <inertia
          ixx="0.01042" ixy="0.001177" ixz="-0.0008871"
          iyy="0.01045" iyz="0.0002226"
          izz="0.01817"/>
      </inertial>
      <visual>
        <geometry>
          <mesh filename="model://Chassis.dae"/>
        </geometry>
      </visual>
      <collision>
        <geometry>
          <mesh filename="model://Chassis_outline.stl"/>
        </geometry>
      </collision>
    </link>


    <!-- Rocker left link -->

    <joint name="rocker_L_joint" type="revolute">
      <origin xyz="0.00263 0.14167 -0.04731" rpy="0 0 3.14"/>
      <parent link="base_link"/>
      <child link="rocker_L_link"/>
      <axis xyz="0 1 0"/>
      <limit effort="100.0" lower="-0.24" upper="0.24" velocity="100.0"/>
      <dynamics friction="1.0" damping="0.1"/>
    </joint>

    <link name="rocker_L_link">
      <inertial>
        <mass value="1.387336"/>
        <origin xyz="0 0.01346 -0.06506"/>
        <inertia
          ixx="0.002956" ixy="-0.000001489324" ixz="-0.000008103407"
          iyy="0.02924"  iyz="0.00007112"
          izz="0.02832"/>
      </inertial>
      <visual>
        <geometry>
          <mesh filename="model://Rocker.dae"/>
        </geometry>
      </visual>
      <collision>
        <geometry>
          <mesh filename="model://Rocker_outline.stl"/>
        </geometry>
      </collision>
    </link>


    <!-- Rocker right link -->

    <joint name="rocker_R_joint" type="revolute">
      <origin xyz="0.00263 -0.14167 -0.04731" rpy="0 0 0"/>
      <parent link="base_link"/>
      <child link="rocker_R_link"/>
      <axis xyz="0 1 0"/>
      <limit effort="100.0" lower="-0.24" upper="0.24" velocity="100.0"/>
      <dynamics friction="1.0" damping="0.1"/> 
      <mimic joint="rocker_L_joint"/>
    </joint>

    <link name="rocker_R_link">
      <inertial>
        <mass value="1.387336"/>
        <origin xyz="0 0.01346 -0.06506"/>
        <inertia
          ixx="0.002956" ixy="-0.000001489324" ixz="-0.000008103407"
          iyy="0.02924"  iyz="0.00007112"
          izz="0.02832"/>
      </inertial>
      <visual>
        <geometry>
          <mesh filename="model://Rocker.dae"/>
        </geometry>
      </visual>
      <collision>
        <geometry>
          <mesh filename="model://Rocker_outline.stl"/>
        </geometry>
      </collision>
    </link>


    <!-- Wheel front-left link -->

    <joint name="wheel_FL_joint" type="continuous">
      <origin xyz="-0.15256 -0.08214 -0.08802" rpy="0 0 0"/>
      <parent link="rocker_L_link"/>
      <child link="wheel_FL_link"/>
      <axis xyz="0 -1 0"/>
      <limit effort="2.0" velocity="6.0"/>
      <dynamics friction="0.3125" damping="0.1"/>
    </joint>

    <link name="wheel_FL_link">
      <inertial>
        <mass value="0.283642"/>
        <origin xyz="0 0.030026 0"/>
        <inertia
          ixx="0.000391"  ixy="0.00000123962" ixz="5.52582e-7"
          iyy="0.0004716" iyz="-0.000002082042"
          izz="0.000391"/>
      </inertial>
      <visual>
        <geometry>
          <mesh filename="model://WheelA.dae"/>
        </geometry>
      </visual>
      <collision>
        <origin xyz="0 0.04485 0" rpy="1.57 0 0"/>
        <geometry>
          <cylinder radius="0.057" length="0.07"/>
        </geometry>
      </collision>
      <collision>
        <origin xyz="0 0.04485 0" rpy="1.57 0 0"/>
        <geometry>
          <cylinder radius="0.0625" length="0.04"/>
        </geometry>
      </collision>
      <collision>
        <geometry>
          <mesh filename="model://Wheel_outline.stl"/>
        </geometry>
      </collision>
    </link>


    <!-- Wheel rear-left link -->

    <joint name="wheel_RL_joint" type="continuous">
      <origin xyz="0.15256 -0.08214 -0.08802" rpy="0 0 0"/>
      <parent link="rocker_L_link"/>
      <child link="wheel_RL_link"/>
      <axis xyz="0 -1 0"/>
      <limit effort="2.0" velocity="6.0"/>
      <dynamics friction="0.3125" damping="0.1"/>
    </joint>

    <link name="wheel_RL_link">
      <inertial>
        <mass value="0.283642"/>
        <origin xyz="0 0.030026 0"/>
        <inertia
          ixx="0.000391"  ixy="0.00000123962" ixz="5.52582e-7"
          iyy="0.0004716" iyz="-0.000002082042"
          izz="0.000391"/>
      </inertial>
      <visual>
        <geometry>
          <mesh filename="model://WheelA.dae"/>
        </geometry>
      </visual>
      <collision>
        <origin xyz="0 0.04485 0" rpy="1.57 0 0"/>
        <geometry>
          <cylinder radius="0.057" length="0.07"/>
        </geometry>
      </collision>
      <collision>
        <origin xyz="0 0.04485 0" rpy="1.57 0 0"/>
        <geometry>
          <cylinder radius="0.0625" length="0.04"/>
        </geometry>
      </collision>
      <collision>
        <geometry>
          <mesh filename="model://Wheel_outline.stl"/>
        </geometry>
      </collision>
    </link>


    <!-- Wheel front-right link -->

    <joint name="wheel_FR_joint" type="continuous">
      <origin xyz="0.15256 -0.08214 -0.08802" rpy="0 0 0"/>
      <parent link="rocker_R_link"/>
      <child link="wheel_FR_link"/>
      <axis xyz="0 1 0"/>
      <limit effort="2.0" velocity="6.0"/>
      <dynamics friction="0.3125" damping="0.1"/>
    </joint>

    <link name="wheel_FR_link">
      <inertial>
        <mass value="0.283642"/>
        <origin xyz="0 0.030026 0"/>
        <inertia
          ixx="0.000391"  ixy="0.00000123962" ixz="5.52582e-7"
          iyy="0.0004716" iyz="-0.000002082042"
          izz="0.000391"/>
      </inertial>
      <visual>
        <geometry>
          <mesh filename="model://WheelB.dae"/>
        </geometry>
      </visual>
      <collision>
        <origin xyz="0 0.04485 0" rpy="1.57 0 0"/>
        <geometry>
          <cylinder radius="0.057" length="0.07"/>
        </geometry>
      </collision>
      <collision>
        <origin xyz="0 0.04485 0" rpy="1.57 0 0"/>
        <geometry>
          <cylinder radius="0.0625" length="0.04"/>
        </geometry>
      </collision>
      <collision>
        <geometry>
          <mesh filename="model://Wheel_outline.stl"/>
        </geometry>
      </collision>
    </link>


    <!-- Wheel rear-right link -->

    <joint name="wheel_RR_joint" type="continuous">
      <origin xyz="-0.15256 -0.08214 -0.08802" rpy="0 0 0"/>
      <parent link="rocker_R_link"/>
      <child link="wheel_RR_link"/>
      <axis xyz="0 1 0"/>
      <limit effort="2.0" velocity="6.0"/>
      <dynamics friction="0.3125" damping="0.1"/> 
    </joint>

    <link name="wheel_RR_link">
      <inertial>
        <mass value="0.283642"/>
        <origin xyz="0 0.030026 0"/>
        <inertia
          ixx="0.000391"  ixy="0.00000123962" ixz="5.52582e-7"
          iyy="0.0004716" iyz="-0.000002082042"
          izz="0.000391"/>
      </inertial>
      <visual>
        <geometry>
          <mesh filename="model://WheelB.dae"/>
        </geometry>
      </visual>
      <collision>
        <origin xyz="0 0.04485 0" rpy="1.57 0 0"/>
        <geometry>
          <cylinder radius="0.057" length="0.07"/>
        </geometry>
      </collision>
      <collision>
        <origin xyz="0 0.04485 0" rpy="1.57 0 0"/>
        <geometry>
          <cylinder radius="0.0625" length="0.04"/>
        </geometry>
      </collision>
      <collision>
        <geometry>
          <mesh filename="model://Wheel_outline.stl"/>
        </geometry>
      </collision>
    </link>


    <!-- Antenna link -->

    <joint name="antenna_joint" type="fixed">
      <origin xyz="-0.0052 0.056 -0.0065" rpy="0 0 0"/>
      <parent link="base_link"/>
      <child link="antenna_link"/>
    </joint>

    <link name="antenna_link">
      <inertial>
        <mass value="0.001237"/>
        <origin xyz="0 0 0.028828"/>
        <inertia
          ixx="2.5529e-7" ixy="0.0" ixz="0.0"
          iyy="2.5529e-7" iyz="0.0"
          izz="1.354e-8"/>
      </inertial>
      <visual>
        <geometry>
          <mesh filename="model://Antenna.dae"/>
        </geometry>
      </visual>
      <collision>
        <origin xyz="0 0 0.028"/>
        <geometry>
          <cylinder radius="0.0055" length="0.056"/>
        </geometry>
      </collision>
    </link>


    <!-- Camera link -->

    <joint name="camera_joint" type="fixed">
      <origin xyz="0.0971 0 -0.0427" rpy="0 0.2094 0"/>
      <parent link="base_link"/>
      <child link="camera_frame"/>
    </joint>

    <link name="camera_frame"/>


    <!-- Camera optical link -->

    <joint name="camera_optical_joint" type="fixed">
      <origin xyz="0 0 0" rpy="-1.57 0.0 -1.57"/>
      <parent link="camera_frame"/>
      <child link="camera_optical_frame"/>
    </joint>

    <link name="camera_optical_frame"/>


    <!-- Imu link -->

    <joint name="imu_joint" type="fixed">
      <origin xyz="0 0 0" rpy="0 0 0"/>
      <parent link="base_link"/>
      <child link="imu_frame"/>
    </joint>

    <link name="imu_frame"/>
    
  <!-- LEO GAZEBO -->

    <gazebo>
      <plugin name="mimic_joint" filename="libmimic_joint_plugin.so">
        <joint>wheel_FL_joint</joint>
        <mimic_joint>wheel_RL_joint</mimic_joint>
      </plugin>
    </gazebo>

    <gazebo>
      <plugin name="mimic_joint" filename="libmimic_joint_plugin.so">
        <joint>wheel_FR_joint</joint>
        <mimic_joint>wheel_RR_joint</mimic_joint>
      </plugin>
    </gazebo>

    <gazebo reference="camera_frame">
      <sensor type="camera" name="camera">
        <always_on>true</always_on>
        <update_rate>30.0</update_rate>
        <visualize>false</visualize> 
        <camera name="leo_camera">
          <horizontal_fov>1.9</horizontal_fov>
          <image>
            <width>640</width>
            <height>480</height>
            <format>R8G8B8</format>
          </image>
          <clip>
            <near>0.02</near>
            <far>300</far>
          </clip>
          <noise>
            <type>gaussian</type>
            <mean>0.0</mean>
            <stddev>0.007</stddev>
          </noise>
          <distortion>
            <k1>-0.279817</k1>
            <k2>0.060321</k2>
            <k3>0.000487</k3>
            <p1>0.000310</p1>
            <p2>0.000000</p2>
            <center>0.5 0.5</center>
          </distortion>
        </camera>
        <plugin name="camera_controller" filename="libgazebo_ros_camera.so">
          <frame_name>camera_optical_frame</frame_name>
        </plugin>
      </sensor>
    </gazebo>

    <!-- rocker differential -->
    <gazebo>
      <plugin name="rocker_differential" filename="libleo_gazebo_differential_plugin.so">
        <jointA>rocker_L_joint</jointA>
        <jointB>rocker_R_joint</jointB>
        <forceConstant>100.0</forceConstant>
      </plugin>
    </gazebo>

    <gazebo>
      <plugin name="differential_drive_controller" filename="libgazebo_ros_diff_drive.so">

        <updateRate>10.0</updateRate>
        <!-- wheels -->
        <left_joint>wheel_FL_joint</left_joint>
        <right_joint>wheel_FR_joint</right_joint>

        <!-- kinematics -->
        <wheel_separation>0.33</wheel_separation>
        <wheel_diameter>0.125</wheel_diameter>

        <!-- output -->
        <publish_odom>true</publish_odom>
        <publish_odom_tf>true</publish_odom_tf>

        <odometry_frame>odom</odometry_frame>
        <robot_base_frame>base_link</robot_base_frame>

      </plugin>
    </gazebo>

    <gazebo reference="imu_frame">
      <sensor type="imu" name="leo_imu_sensor">
        <update_rate>100</update_rate>
        <plugin filename="libgazebo_ros_imu_sensor.so" name="imu_plugin">
          <topicName>imu/data_raw</topicName>
          <frameName>imu_frame</frameName>
          <updateRateHZ>100.0</updateRateHZ>
          <gaussianNoise>0.01</gaussianNoise>
          <initialOrientationAsReference>false</initialOrientationAsReference>
        </plugin>
      </sensor>
    </gazebo>

    <ros2_control name="GazeboSystem" type="system">
      <hardware>
        <plugin>gazebo_ros2_control/GazeboSystem</plugin>
      </hardware>
      <joint name="rocker_L_joint">
        <state_interface name="position"/>
      </joint>
      <joint name="rocker_R_joint">
        <state_interface name="position"/>
      </joint>
      <joint name="wheel_FL_joint">
        <command_interface name="velocity">
          <param name="min">-6</param>
          <param name="max">6</param>
        </command_interface>
        <state_interface name="position"/>
        <state_interface name="velocity"/>
        <state_interface name="effort"/>
      </joint>
      <joint name="wheel_RL_joint">
        <command_interface name="velocity">
          <param name="min">-6</param>
          <param name="max">6</param>
        </command_interface>
        <state_interface name="position"/>
        <state_interface name="velocity"/>
        <state_interface name="effort"/>
      </joint>
      <joint name="wheel_FR_joint">
        <command_interface name="velocity">
          <param name="min">-6</param>
          <param name="max">6</param>
        </command_interface>
        <state_interface name="position"/>
        <state_interface name="velocity"/>
        <state_interface name="effort"/>
      </joint>
      <joint name="wheel_RR_joint">
        <command_interface name="velocity">
          <param name="min">-6</param>
          <param name="max">6</param>
        </command_interface>
        <state_interface name="position"/>
        <state_interface name="velocity"/>
        <state_interface name="effort"/>
      </joint>
    </ros2_control>

    <gazebo>
      <plugin name="gazebo_ros2_control" filename="libgazebo_ros2_control.so">
        <robot_param>robot_description</robot_param>
        <robot_param_node>robot_state_publisher</robot_param_node>
        <parameters>$(find leo_rover_description)/config/controllers.yaml</parameters>
      </plugin>
    </gazebo>

</robot>